ERROR:my_app:Exception on / [GET]
Traceback (most recent call last):
  File "/usr/local/lib/python3.11/site-packages/flask/app.py", line 1463, in wsgi_app
    response = self.full_dispatch_request()
               ^^^^^^^^^^^^^^^^^^^^^^^^^^^^
  File "/usr/local/lib/python3.11/site-packages/flask/app.py", line 872, in full_dispatch_request
    rv = self.handle_user_exception(e)
         ^^^^^^^^^^^^^^^^^^^^^^^^^^^^^
  File "/usr/local/lib/python3.11/site-packages/flask/app.py", line 870, in full_dispatch_request
    rv = self.dispatch_request()
         ^^^^^^^^^^^^^^^^^^^^^^^
  File "/usr/local/lib/python3.11/site-packages/flask/app.py", line 855, in dispatch_request
    return self.ensure_sync(self.view_functions[rule.endpoint])(**view_args)  # type: ignore[no-any-return]
           ^^^^^^^^^^^^^^^^^^^^^^^^^^^^^^^^^^^^^^^^^^^^^^^^^^^^^^^^^^^^^^^^^
  File "/app/my_app.py", line 20, in index
    qr_code_stream = generate_and_save_qr_code(data, logo)
                     ^^^^^^^^^^^^^^^^^^^^^^^^^^^^^^^^^^^^^
  File "/app/main.py", line 78, in generate_and_save_qr_code
    img = apply_logo(img, logo_path)
          ^^^^^^^^^^^^^^^^^^^^^^^^^^
  File "/app/main.py", line 105, in apply_logo
    logo = check_if_logo_path_is_local_or_remote(logo_path)
           ^^^^^^^^^^^^^^^^^^^^^^^^^^^^^^^^^^^^^^^^^^^^^^^^
  File "/app/main.py", line 142, in check_if_logo_path_is_local_or_remote
    return Image.open(logo_path)
           ^^^^^^^^^^^^^^^^^^^^^
  File "/usr/local/lib/python3.11/site-packages/PIL/Image.py", line 3309, in open
    raise UnidentifiedImageError(msg)
PIL.UnidentifiedImageError: cannot identify image file './icons/dwellingsvg.svg'
INFO:root: Dwelling Logo.png took 0.627650260925293 seconds.
